<?xml version="1.0" ?>
<!-- =================================================================================== -->
<!-- |    This document was autogenerated by xacro from segbot_v2.arm.urdf.xacro       | -->
<!-- |    EDITING THIS FILE BY HAND IS NOT RECOMMENDED                                 | -->
<!-- =================================================================================== -->
<robot name="segbot" xmlns:body="http://playerstage.sourceforge.net/gazebo/xmlschema/#body" xmlns:controller="http://playerstage.sourceforge.net/gazebo/xmlschema/#controller" xmlns:gazebo="http://playerstage.sourceforge.net/gazebo/xmlschema/#gz" xmlns:geom="http://playerstage.sourceforge.net/gazebo/xmlschema/#geom" xmlns:interface="http://playerstage.sourceforge.net/gazebo/xmlschema/#interface" xmlns:joint="http://playerstage.sourceforge.net/gazebo/xmlschema/#joint" xmlns:model="http://playerstage.sourceforge.net/gazebo/xmlschema/#model" xmlns:physics="http://playerstage.sourceforge.net/gazebo/xmlschema/#physics" xmlns:renderable="http://playerstage.sourceforge.net/gazebo/xmlschema/#renderable" xmlns:rendering="http://playerstage.sourceforge.net/gazebo/xmlschema/#rendering" xmlns:sensor="http://playerstage.sourceforge.net/gazebo/xmlschema/#sensor" xmlns:xacro="http://ros.org/wiki/xacro" xmlns:xi="http://www.w3.org/2001/XInclude">
  <!-- Included URDF Files -->
  <material name="light_grey">
    <color rgba="0.7 0.7 0.7 1"/>
  </material>
  <material name="dark_grey">
    <color rgba="0.5 0.5 0.5 1"/>
  </material>
  <material name="black">
    <color rgba="0 0 0 1"/>
  </material>
  <material name="almost_black">
    <color rgba="0.02 0.02 0.02 1"/>
  </material>
  <!-- Add the segbot base -->
  <link name="base_footprint">
    <visual>
      <origin rpy="0 0 0" xyz="0 0 0"/>
      <geometry>
        <box size="0.001 0.001 0.001"/>
      </geometry>
    </visual>
  </link>
  <joint name="base_footprint_joint" type="fixed">
    <origin rpy="0 0 0" xyz="0.0 0 0.2165"/>
    <parent link="base_footprint"/>
    <child link="base_link"/>
  </joint>
  <link name="base_link">
    <inertial>
      <mass value="30"/>
      <origin xyz="0 0 -0.2165"/>
      <inertia ixx="3000.0" ixy="0.0" ixz="0.0" iyy="3000.0" iyz="0.0" izz="30.0"/>
    </inertial>
    <visual>
      <origin rpy="0 0 0" xyz="0 0 0"/>
      <geometry>
        <mesh filename="package://segbot_description/meshes/rmp50-base-link.dae" scale="0.0254 0.0254 0.0254"/>
      </geometry>
    </visual>
    <collision>
      <origin rpy="0 0 0" xyz="0 0 -0.05"/>
      <geometry>
        <cylinder length="0.3330" radius="0.305"/>
      </geometry>
    </collision>
  </link>
  <joint name="laser_obstacle_joint" type="fixed">
    <origin rpy="0 0 0" xyz="0.0 0 0.3165"/>
    <parent link="base_link"/>
    <child link="laser_obstacle"/>
  </joint>
  <link name="laser_obstacle">
    <inertial>
      <mass value="0.1"/>
      <origin rpy="0 0 0" xyz="0 0 0"/>
      <inertia ixx="0.01" ixy="0.0" ixz="0.0" iyy="0.01" iyz="0.0" izz="0.01"/>
    </inertial>
    <visual>
      <origin rpy="0 0 0" xyz="0 0 0"/>
      <geometry>
        <box size="0.001 0.001 0.001"/>
      </geometry>
    </visual>
    <collision>
      <origin rpy="0 0 0" xyz="0 0 0"/>
      <geometry>
        <box size="0.25 0.6 0.4"/>
      </geometry>
    </collision>
  </link>
  <gazebo reference="base_link">
    <mu1 value="100.0"/>
    <mu2 value="100.0"/>
    <kp value="1000000.0"/>
    <kd value="1.0"/>
  </gazebo>
  <joint name="base_caster_support_joint" type="continuous">
    <origin rpy="0 0 0" xyz="-0.3292 0 -0.0485"/>
    <parent link="base_link"/>
    <child link="base_caster_support_link"/>
    <axis xyz="0 0 1"/>
    <anchor xyz="0.01 0 0"/>
    <limit effort="100" k_velocity="0" velocity="100"/>
    <joint_properties damping="0.0" friction="0.0"/>
  </joint>
  <transmission name="base_caster_support_trans" type="pr2_mechanism_model/SimpleTransmission">
    <actuator name="base_caster_support_motor"/>
    <joint name="base_caster_support_joint"/>
    <mechanicalReduction>1.0</mechanicalReduction>
  </transmission>
  <link name="base_caster_support_link">
    <inertial>
      <mass value="1"/>
      <origin xyz="0 0 0"/>
      <inertia ixx="0.00375" ixy="0.0" ixz="0.0" iyy="0.00375" iyz="0.0" izz="0.00375"/>
    </inertial>
    <visual>
      <origin rpy="0 0 0" xyz="0 0 0"/>
      <geometry>
        <mesh filename="package://segbot_description/meshes/rmp50-castor-link.dae" scale="0.0254 0.0254 0.0254"/>
      </geometry>
    </visual>
  </link>
  <gazebo reference="base_caster_support_link">
    <mu1 value="100.0"/>
    <mu2 value="100.0"/>
    <kp value="1000000.0"/>
    <kd value="1.0"/>
  </gazebo>
  <joint name="caster_wheel_joint" type="continuous">
    <origin rpy="0 0 0" xyz="-0.0397 0 -0.0918"/>
    <parent link="base_caster_support_link"/>
    <child link="caster_wheel_link"/>
    <axis xyz="0 1 0"/>
    <anchor xyz="0 0 0"/>
    <limit effort="100" k_velocity="0" velocity="100"/>
    <joint_properties damping="0.0" friction="0.0"/>
  </joint>
  <transmission name="caster_wheel_trans" type="pr2_mechanism_model/SimpleTransmission">
    <actuator name="caster_wheel_motor"/>
    <joint name="caster_wheel_joint"/>
    <mechanicalReduction>1.0</mechanicalReduction>
  </transmission>
  <link name="caster_wheel_link">
    <inertial>
      <mass value="2"/>
      <origin rpy="0 0 0" xyz="0 0 0"/>
      <inertia ixx="0.003" ixy="0.0" ixz="0.0" iyy="0.00581" iyz="0.0" izz="0.003"/>
    </inertial>
    <visual>
      <origin rpy="0 0 0" xyz="0 0 0"/>
      <geometry>
        <mesh filename="package://segbot_description/meshes/rmp50-castor-wheel.dae" scale="0.0254 0.0254 0.0254"/>
      </geometry>
    </visual>
  </link>
  <gazebo reference="caster_wheel_link">
    <mu1 value="10.0"/>
    <mu2 value="10.0"/>
    <kp value="1000000.0"/>
    <kd value="1.0"/>
  </gazebo>
  <joint name="base_link_left_wheel_joint" type="continuous">
    <origin rpy="0 0 0" xyz="0 0.2689 0.0239"/>
    <axis xyz="0 1 0"/>
    <anchor xyz="0 0 0"/>
    <limit effort="100" velocity="100"/>
    <joint_properties damping="0.0" friction="0.0"/>
    <parent link="base_link"/>
    <child link="base_link_left_wheel_link"/>
  </joint>
  <link name="base_link_left_wheel_link">
    <inertial>
      <mass value="5"/>
      <origin xyz=" 0 0 0 "/>
      <inertia ixx="0.076" ixy="0.0" ixz="0.0" iyy="0.144" iyz="0.0" izz="0.076"/>
    </inertial>
    <visual>
      <origin rpy="0 0 0" xyz="0 0 0"/>
      <geometry>
        <mesh filename="package://segbot_description/meshes/rmp50-left-wheel.dae" scale="0.0254 0.0254 0.0254"/>
      </geometry>
    </visual>
  </link>
  <gazebo reference="base_link_left_wheel_link">
    <mu1 value="10.0"/>
    <mu2 value="10.0"/>
    <kp value="1000000.0"/>
    <kd value="1.0"/>
  </gazebo>
  <transmission name="base_link_left_wheel_trans" type="pr2_mechanism_model/SimpleTransmission">
    <actuator name="base_link_left_wheel_motor"/>
    <joint name="base_link_left_wheel_joint"/>
    <mechanicalReduction>1.0</mechanicalReduction>
  </transmission>
  <joint name="base_link_right_wheel_joint" type="continuous">
    <origin rpy="0 0 0" xyz="0 -0.2689 0.0239"/>
    <axis xyz="0 1 0"/>
    <anchor xyz="0 0 0"/>
    <limit effort="100" velocity="100"/>
    <joint_properties damping="0.0" friction="0.0"/>
    <parent link="base_link"/>
    <child link="base_link_right_wheel_link"/>
  </joint>
  <link name="base_link_right_wheel_link">
    <inertial>
      <mass value="5"/>
      <origin xyz=" 0 0 0 "/>
      <inertia ixx="0.076" ixy="0.0" ixz="0.0" iyy="0.144" iyz="0.0" izz="0.076"/>
    </inertial>
    <visual>
      <origin rpy="0 0 0" xyz="0 0 0"/>
      <geometry>
        <mesh filename="package://segbot_description/meshes/rmp50-right-wheel.dae" scale="0.0254 0.0254 0.0254"/>
      </geometry>
    </visual>
  </link>
  <gazebo reference="base_link_right_wheel_link">
    <mu1 value="10.0"/>
    <mu2 value="10.0"/>
    <kp value="1000000.0"/>
    <kd value="1.0"/>
  </gazebo>
  <transmission name="base_link_right_wheel_trans" type="pr2_mechanism_model/SimpleTransmission">
    <actuator name="base_link_right_wheel_motor"/>
    <joint name="base_link_right_wheel_joint"/>
    <mechanicalReduction>1.0</mechanicalReduction>
  </transmission>
  <joint name="chassis_base_plate_joint" type="fixed">
    <origin xyz="0.0 0 0.10795"/>
    <parent link="base_link"/>
    <child link="chassis_base_plate_link"/>
  </joint>
  <link name="chassis_base_plate_link">
    <inertial>
      <mass value="0.1"/>
      <origin rpy="0 0 0" xyz="0 0 0"/>
      <inertia ixx="0.01" ixy="0.0" ixz="0.0" iyy="0.01" iyz="0.0" izz="0.01"/>
    </inertial>
    <visual>
      <origin rpy="0 0 0" xyz="0 0 0.003175"/>
      <geometry>
        <box size="0.4064 0.3556 0.00635"/>
      </geometry>
      <material name="dark_grey"/>
    </visual>
  </link>
  <gazebo reference="chassis_base_plate_link">
    <material>Gazebo/Grey</material>
    <mu1 value="100.0"/>
    <mu2 value="100.0"/>
    <kp value="1000000.0"/>
    <kd value="1.0"/>
  </gazebo>
  <joint name="chassis_left_plate_joint" type="fixed">
    <origin rpy="-1.5707963268 0 0" xyz="0 0.17145 -0.0508"/>
    <parent link="chassis_base_plate_link"/>
    <child link="chassis_left_plate_link"/>
  </joint>
  <link name="chassis_left_plate_link">
    <inertial>
      <mass value="0.1"/>
      <origin rpy="0 0 0" xyz="0 0 0"/>
      <inertia ixx="0.01" ixy="0.0" ixz="0.0" iyy="0.01" iyz="0.0" izz="0.01"/>
    </inertial>
    <visual>
      <origin rpy="0 0 0" xyz="0 0 0.003175"/>
      <geometry>
        <box size="0.4064 0.1016 0.00635"/>
      </geometry>
      <material name="dark_grey"/>
    </visual>
  </link>
  <gazebo reference="chassis_left_plate_link">
    <material>Gazebo/Grey</material>
    <mu1 value="100.0"/>
    <mu2 value="100.0"/>
    <kp value="1000000.0"/>
    <kd value="1.0"/>
  </gazebo>
  <joint name="chassis_right_plate_joint" type="fixed">
    <origin rpy="+1.5707963268 0 0" xyz="0 -0.17145 -0.0508"/>
    <parent link="chassis_base_plate_link"/>
    <child link="chassis_right_plate_link"/>
  </joint>
  <link name="chassis_right_plate_link">
    <inertial>
      <mass value="0.1"/>
      <origin rpy="0 0 0" xyz="0 0 0"/>
      <inertia ixx="0.01" ixy="0.0" ixz="0.0" iyy="0.01" iyz="0.0" izz="0.01"/>
    </inertial>
    <visual>
      <origin rpy="0 0 0" xyz="0 0 0.003175"/>
      <geometry>
        <box size="0.4064 0.1016 0.00635"/>
      </geometry>
      <material name="dark_grey"/>
    </visual>
  </link>
  <gazebo reference="chassis_right_plate_link">
    <material>Gazebo/Grey</material>
    <mu1 value="100.0"/>
    <mu2 value="100.0"/>
    <kp value="1000000.0"/>
    <kd value="1.0"/>
  </gazebo>
  <joint name="battery_box_joint" type="fixed">
    <origin rpy="0 0 0" xyz="-0.0508 0 0.00635"/>
    <parent link="chassis_base_plate_link"/>
    <child link="battery_box_link"/>
  </joint>
  <link name="battery_box_link">
    <inertial>
      <mass value="0.1"/>
      <origin rpy="0 0 0" xyz="0 0 0"/>
      <inertia ixx="0.01" ixy="0.0" ixz="0.0" iyy="0.01" iyz="0.0" izz="0.01"/>
    </inertial>
    <visual>
      <origin rpy="0 0 0" xyz="0 0 0.1397"/>
      <geometry>
        <box size="0.1778 0.3556 0.2794"/>
      </geometry>
      <material name="almost_black"/>
    </visual>
  </link>
  <gazebo reference="battery_box_link">
    <material>Gazebo/Black</material>
    <mu1 value="100.0"/>
    <mu2 value="100.0"/>
    <kp value="1000000.0"/>
    <kd value="1.0"/>
  </gazebo>
  <joint name="front_base_beam_joint" type="fixed">
    <origin rpy="1.5707963268 0 0" xyz="0.1143 0.1524 0.01905"/>
    <parent link="chassis_base_plate_link"/>
    <child link="front_base_beam_link"/>
  </joint>
  <link name="front_base_beam_link">
    <inertial>
      <mass value="0.1"/>
      <inertia ixx="0.01" ixy="0.0" ixz="0.0" iyy="0.01" iyz="0.0" izz="0.01"/>
    </inertial>
    <visual>
      <origin rpy="0 0 0" xyz="0 0 0.1524"/>
      <geometry>
        <box size="0.0254 0.0254 0.3048"/>
      </geometry>
      <material name="light_grey"/>
    </visual>
  </link>
  <gazebo reference="front_base_beam_link">
    <material>Gazebo/Grey</material>
    <mu1 value="100.0"/>
    <mu2 value="100.0"/>
    <kp value="1000000.0"/>
    <kd value="1.0"/>
  </gazebo>
  <joint name="back_base_beam_joint" type="fixed">
    <origin rpy="1.5707963268 0 0" xyz="-0.1651 0.1524 0.01905"/>
    <parent link="chassis_base_plate_link"/>
    <child link="back_base_beam_link"/>
  </joint>
  <link name="back_base_beam_link">
    <inertial>
      <mass value="0.1"/>
      <inertia ixx="0.01" ixy="0.0" ixz="0.0" iyy="0.01" iyz="0.0" izz="0.01"/>
    </inertial>
    <visual>
      <origin rpy="0 0 0" xyz="0 0 0.1524"/>
      <geometry>
        <box size="0.0254 0.0254 0.3048"/>
      </geometry>
      <material name="light_grey"/>
    </visual>
  </link>
  <gazebo reference="back_base_beam_link">
    <material>Gazebo/Grey</material>
    <mu1 value="100.0"/>
    <mu2 value="100.0"/>
    <kp value="1000000.0"/>
    <kd value="1.0"/>
  </gazebo>
  <joint name="back_left_vertical_beam_joint" type="fixed">
    <origin rpy="-1.5707963268 0 0" xyz="0 0 0.0127"/>
    <parent link="back_base_beam_link"/>
    <child link="back_left_vertical_beam_link"/>
  </joint>
  <link name="back_left_vertical_beam_link">
    <inertial>
      <mass value="0.1"/>
      <inertia ixx="0.01" ixy="0.0" ixz="0.0" iyy="0.01" iyz="0.0" izz="0.01"/>
    </inertial>
    <visual>
      <origin rpy="0 0 0" xyz="0 0 0.2286"/>
      <geometry>
        <box size="0.0254 0.0254 0.4572"/>
      </geometry>
      <material name="light_grey"/>
    </visual>
  </link>
  <gazebo reference="back_left_vertical_beam_link">
    <material>Gazebo/Grey</material>
    <mu1 value="100.0"/>
    <mu2 value="100.0"/>
    <kp value="1000000.0"/>
    <kd value="1.0"/>
  </gazebo>
  <joint name="front_left_vertical_beam_joint" type="fixed">
    <origin rpy="-1.5707963268 0 0" xyz="0 0 0.0127"/>
    <parent link="front_base_beam_link"/>
    <child link="front_left_vertical_beam_link"/>
  </joint>
  <link name="front_left_vertical_beam_link">
    <inertial>
      <mass value="0.1"/>
      <inertia ixx="0.01" ixy="0.0" ixz="0.0" iyy="0.01" iyz="0.0" izz="0.01"/>
    </inertial>
    <visual>
      <origin rpy="0 0 0" xyz="0 0 0.2286"/>
      <geometry>
        <box size="0.0254 0.0254 0.4572"/>
      </geometry>
      <material name="light_grey"/>
    </visual>
  </link>
  <gazebo reference="front_left_vertical_beam_link">
    <material>Gazebo/Grey</material>
    <mu1 value="100.0"/>
    <mu2 value="100.0"/>
    <kp value="1000000.0"/>
    <kd value="1.0"/>
  </gazebo>
  <joint name="back_right_vertical_beam_joint" type="fixed">
    <origin rpy="-1.5707963268 0 0" xyz="0 0 0.2921"/>
    <parent link="back_base_beam_link"/>
    <child link="back_right_vertical_beam_link"/>
  </joint>
  <link name="back_right_vertical_beam_link">
    <inertial>
      <mass value="0.1"/>
      <inertia ixx="0.01" ixy="0.0" ixz="0.0" iyy="0.01" iyz="0.0" izz="0.01"/>
    </inertial>
    <visual>
      <origin rpy="0 0 0" xyz="0 0 0.2286"/>
      <geometry>
        <box size="0.0254 0.0254 0.4572"/>
      </geometry>
      <material name="light_grey"/>
    </visual>
  </link>
  <gazebo reference="back_right_vertical_beam_link">
    <material>Gazebo/Grey</material>
    <mu1 value="100.0"/>
    <mu2 value="100.0"/>
    <kp value="1000000.0"/>
    <kd value="1.0"/>
  </gazebo>
  <joint name="front_right_vertical_beam_joint" type="fixed">
    <origin rpy="-1.5707963268 0 0" xyz="0 0 0.2921"/>
    <parent link="front_base_beam_link"/>
    <child link="front_right_vertical_beam_link"/>
  </joint>
  <link name="front_right_vertical_beam_link">
    <inertial>
      <mass value="0.1"/>
      <inertia ixx="0.01" ixy="0.0" ixz="0.0" iyy="0.01" iyz="0.0" izz="0.01"/>
    </inertial>
    <visual>
      <origin rpy="0 0 0" xyz="0 0 0.2286"/>
      <geometry>
        <box size="0.0254 0.0254 0.4572"/>
      </geometry>
      <material name="light_grey"/>
    </visual>
  </link>
  <gazebo reference="front_right_vertical_beam_link">
    <material>Gazebo/Grey</material>
    <mu1 value="100.0"/>
    <mu2 value="100.0"/>
    <kp value="1000000.0"/>
    <kd value="1.0"/>
  </gazebo>
  <joint name="left_laptop_support_beam_joint" type="fixed">
    <origin rpy="3.14159265359 -1.5707963268 0" xyz="-0.0127 0.0254 0.4445"/>
    <parent link="back_left_vertical_beam_link"/>
    <child link="left_laptop_support_beam_link"/>
  </joint>
  <link name="left_laptop_support_beam_link">
    <inertial>
      <mass value="0.1"/>
      <inertia ixx="0.01" ixy="0.0" ixz="0.0" iyy="0.01" iyz="0.0" izz="0.01"/>
    </inertial>
    <visual>
      <origin rpy="0 0 0" xyz="0 0 0.1524"/>
      <geometry>
        <box size="0.0254 0.0254 0.3048"/>
      </geometry>
      <material name="light_grey"/>
    </visual>
  </link>
  <gazebo reference="left_laptop_support_beam_link">
    <material>Gazebo/Grey</material>
    <mu1 value="100.0"/>
    <mu2 value="100.0"/>
    <kp value="1000000.0"/>
    <kd value="1.0"/>
  </gazebo>
  <joint name="right_laptop_support_beam_joint" type="fixed">
    <origin rpy="3.14159265359 -1.5707963268 0" xyz="-0.0127 -0.0254 0.4445"/>
    <parent link="back_right_vertical_beam_link"/>
    <child link="right_laptop_support_beam_link"/>
  </joint>
  <link name="right_laptop_support_beam_link">
    <inertial>
      <mass value="0.1"/>
      <inertia ixx="0.01" ixy="0.0" ixz="0.0" iyy="0.01" iyz="0.0" izz="0.01"/>
    </inertial>
    <visual>
      <origin rpy="0 0 0" xyz="0 0 0.1524"/>
      <geometry>
        <box size="0.0254 0.0254 0.3048"/>
      </geometry>
      <material name="light_grey"/>
    </visual>
  </link>
  <gazebo reference="right_laptop_support_beam_link">
    <material>Gazebo/Grey</material>
    <mu1 value="100.0"/>
    <mu2 value="100.0"/>
    <kp value="1000000.0"/>
    <kd value="1.0"/>
  </gazebo>
  <joint name="laptop_base_plate_joint" type="fixed">
    <origin rpy="3.14159265359 -1.5707963268 0" xyz="0.0127 0.1651 0.1524"/>
    <parent link="left_laptop_support_beam_link"/>
    <child link="laptop_base_plate_link"/>
  </joint>
  <link name="laptop_base_plate_link">
    <inertial>
      <mass value="0.1"/>
      <origin rpy="0 0 0" xyz="0 0 0"/>
      <inertia ixx="0.01" ixy="0.0" ixz="0.0" iyy="0.01" iyz="0.0" izz="0.01"/>
    </inertial>
    <visual>
      <origin rpy="0 0 0" xyz="0 0 0.0015875"/>
      <geometry>
        <box size="0.4064 0.4572 0.003175"/>
      </geometry>
      <material name="dark_grey"/>
    </visual>
  </link>
  <gazebo reference="laptop_base_plate_link">
    <material>Gazebo/Grey</material>
    <mu1 value="100.0"/>
    <mu2 value="100.0"/>
    <kp value="1000000.0"/>
    <kd value="1.0"/>
  </gazebo>
  <joint name="laptop_joint" type="fixed">
    <origin rpy="0 0 0" xyz="-0.0762 0 0.003175"/>
    <parent link="laptop_base_plate_link"/>
    <child link="laptop_link"/>
  </joint>
  <link name="laptop_link">
    <inertial>
      <mass value="0.1"/>
      <origin rpy="0 0 0" xyz="0 0 0"/>
      <inertia ixx="0.01" ixy="0.0" ixz="0.0" iyy="0.01" iyz="0.0" izz="0.01"/>
    </inertial>
    <visual>
      <origin rpy="0 0 0" xyz="0 0 0.009525"/>
      <geometry>
        <box size="0.2286 0.3048 0.01905"/>
      </geometry>
      <material name="almost_black"/>
    </visual>
  </link>
  <gazebo reference="laptop_link">
    <material>Gazebo/Grey</material>
    <mu1 value="100.0"/>
    <mu2 value="100.0"/>
    <kp value="1000000.0"/>
    <kd value="1.0"/>
  </gazebo>
  <joint name="laptop_screen_joint" type="fixed">
    <origin rpy="0 -1.5707963268 0" xyz="0.1143 0 0.01905"/>
    <parent link="laptop_link"/>
    <child link="laptop_screen_link"/>
  </joint>
  <link name="laptop_screen_link">
    <inertial>
      <mass value="0.1"/>
      <origin rpy="0 0 0" xyz="0 0 0"/>
      <inertia ixx="0.01" ixy="0.0" ixz="0.0" iyy="0.01" iyz="0.0" izz="0.01"/>
    </inertial>
    <visual>
      <origin rpy="0 0 -1.5707963268" xyz="0.1143 0 -0.009525"/>
      <geometry>
        <box size="0.3048 0.2286 0.01905"/>
      </geometry>
      <material name="almost_black"/>
    </visual>
  </link>
  <gazebo reference="laptop_screen_link">
    <visual>
      <plugin filename="libgazebo_ros_video.so" name="laptop_video_controller">
        <height>120</height>
        <width>160</width>
        <topicName>image</topicName>
      </plugin>
    </visual>
    <material>Gazebo/Grey</material>
    <mu1 value="100.0"/>
    <mu2 value="100.0"/>
    <kp value="1000000.0"/>
    <kd value="1.0"/>
  </gazebo>
  <!-- Add the forward facing kinect sensor for navigation -->
  <joint name="nav_kinect_sensor_beam_joint" type="fixed">
    <origin rpy="-1.5707963268 -1.5707963268 0" xyz="0.0254 -0.0127 0.2921"/>
    <parent link="back_right_vertical_beam_link"/>
    <child link="nav_kinect_sensor_beam_link"/>
  </joint>
  <link name="nav_kinect_sensor_beam_link">
    <inertial>
      <mass value="0.1"/>
      <inertia ixx="0.01" ixy="0.0" ixz="0.0" iyy="0.01" iyz="0.0" izz="0.01"/>
    </inertial>
    <visual>
      <origin rpy="0 0 0" xyz="0 0 0.1524"/>
      <geometry>
        <box size="0.0254 0.0254 0.3048"/>
      </geometry>
      <material name="light_grey"/>
    </visual>
  </link>
  <gazebo reference="nav_kinect_sensor_beam_link">
    <material>Gazebo/Grey</material>
    <mu1 value="100.0"/>
    <mu2 value="100.0"/>
    <kp value="1000000.0"/>
    <kd value="1.0"/>
  </gazebo>
  <joint name="nav_kinect_base_plate_joint" type="fixed">
    <origin rpy="1.5707963268 0 1.5707963268" xyz="0.0127 0 0.1524"/>
    <parent link="nav_kinect_sensor_beam_link"/>
    <child link="nav_kinect_base_plate_link"/>
  </joint>
  <link name="nav_kinect_base_plate_link">
    <inertial>
      <mass value="0.1"/>
      <origin rpy="0 0 0" xyz="0 0 0"/>
      <inertia ixx="0.01" ixy="0.0" ixz="0.0" iyy="0.01" iyz="0.0" izz="0.01"/>
    </inertial>
    <visual>
      <origin rpy="0 0 0" xyz="0 0 0.00079375"/>
      <geometry>
        <box size="0.1016 0.2286 0.0015875"/>
      </geometry>
      <material name="dark_grey"/>
    </visual>
  </link>
  <gazebo reference="nav_kinect_base_plate_link">
    <material>Gazebo/Grey</material>
    <mu1 value="100.0"/>
    <mu2 value="100.0"/>
    <kp value="1000000.0"/>
    <kd value="1.0"/>
  </gazebo>
  <joint name="nav_kinect_standoff_1_joint" type="fixed">
    <origin rpy="0 0 0" xyz="0.0381 -0.1016 0.0015875"/>
    <parent link="nav_kinect_base_plate_link"/>
    <child link="nav_kinect_standoff_1_link"/>
  </joint>
  <link name="nav_kinect_standoff_1_link">
    <inertial>
      <mass value="0.1"/>
      <origin rpy="0 0 0" xyz="0 0 0"/>
      <inertia ixx="0.01" ixy="0.0" ixz="0.0" iyy="0.01" iyz="0.0" izz="0.01"/>
    </inertial>
    <visual>
      <origin rpy="0 0 0" xyz="0 0 0.0254"/>
      <geometry>
        <cylinder length="0.0508" radius="0.003175"/>
      </geometry>
      <material name="light_grey"/>
    </visual>
  </link>
  <gazebo reference="nav_kinect_standoff_1_link">
    <material>Gazebo/Grey</material>
    <mu1 value="100.0"/>
    <mu2 value="100.0"/>
    <kp value="1000000.0"/>
    <kd value="1.0"/>
  </gazebo>
  <joint name="nav_kinect_standoff_2_joint" type="fixed">
    <origin rpy="0 0 0" xyz="0.0381 0.1016 0.0015875"/>
    <parent link="nav_kinect_base_plate_link"/>
    <child link="nav_kinect_standoff_2_link"/>
  </joint>
  <link name="nav_kinect_standoff_2_link">
    <inertial>
      <mass value="0.1"/>
      <origin rpy="0 0 0" xyz="0 0 0"/>
      <inertia ixx="0.01" ixy="0.0" ixz="0.0" iyy="0.01" iyz="0.0" izz="0.01"/>
    </inertial>
    <visual>
      <origin rpy="0 0 0" xyz="0 0 0.0254"/>
      <geometry>
        <cylinder length="0.0508" radius="0.003175"/>
      </geometry>
      <material name="light_grey"/>
    </visual>
  </link>
  <gazebo reference="nav_kinect_standoff_2_link">
    <material>Gazebo/Grey</material>
    <mu1 value="100.0"/>
    <mu2 value="100.0"/>
    <kp value="1000000.0"/>
    <kd value="1.0"/>
  </gazebo>
  <joint name="nav_kinect_standoff_3_joint" type="fixed">
    <origin rpy="0 0 0" xyz="-0.0381 0.1016 0.0015875"/>
    <parent link="nav_kinect_base_plate_link"/>
    <child link="nav_kinect_standoff_3_link"/>
  </joint>
  <link name="nav_kinect_standoff_3_link">
    <inertial>
      <mass value="0.1"/>
      <origin rpy="0 0 0" xyz="0 0 0"/>
      <inertia ixx="0.01" ixy="0.0" ixz="0.0" iyy="0.01" iyz="0.0" izz="0.01"/>
    </inertial>
    <visual>
      <origin rpy="0 0 0" xyz="0 0 0.0254"/>
      <geometry>
        <cylinder length="0.0508" radius="0.003175"/>
      </geometry>
      <material name="light_grey"/>
    </visual>
  </link>
  <gazebo reference="nav_kinect_standoff_3_link">
    <material>Gazebo/Grey</material>
    <mu1 value="100.0"/>
    <mu2 value="100.0"/>
    <kp value="1000000.0"/>
    <kd value="1.0"/>
  </gazebo>
  <joint name="nav_kinect_standoff_4_joint" type="fixed">
    <origin rpy="0 0 0" xyz="-0.0381 -0.1016 0.0015875"/>
    <parent link="nav_kinect_base_plate_link"/>
    <child link="nav_kinect_standoff_4_link"/>
  </joint>
  <link name="nav_kinect_standoff_4_link">
    <inertial>
      <mass value="0.1"/>
      <origin rpy="0 0 0" xyz="0 0 0"/>
      <inertia ixx="0.01" ixy="0.0" ixz="0.0" iyy="0.01" iyz="0.0" izz="0.01"/>
    </inertial>
    <visual>
      <origin rpy="0 0 0" xyz="0 0 0.0254"/>
      <geometry>
        <cylinder length="0.0508" radius="0.003175"/>
      </geometry>
      <material name="light_grey"/>
    </visual>
  </link>
  <gazebo reference="nav_kinect_standoff_4_link">
    <material>Gazebo/Grey</material>
    <mu1 value="100.0"/>
    <mu2 value="100.0"/>
    <kp value="1000000.0"/>
    <kd value="1.0"/>
  </gazebo>
  <joint name="nav_kinect_top_plate_joint" type="fixed">
    <origin rpy="0 0 0" xyz="-0.0381 0.1016 0.0508"/>
    <parent link="nav_kinect_standoff_1_link"/>
    <child link="nav_kinect_top_plate_link"/>
  </joint>
  <link name="nav_kinect_top_plate_link">
    <inertial>
      <mass value="0.1"/>
      <origin rpy="0 0 0" xyz="0 0 0"/>
      <inertia ixx="0.01" ixy="0.0" ixz="0.0" iyy="0.01" iyz="0.0" izz="0.01"/>
    </inertial>
    <visual>
      <origin rpy="0 0 0" xyz="0 0 0.00079375"/>
      <geometry>
        <box size="0.1016 0.2286 0.0015875"/>
      </geometry>
      <material name="dark_grey"/>
    </visual>
  </link>
  <gazebo reference="nav_kinect_top_plate_link">
    <material>Gazebo/Grey</material>
    <mu1 value="100.0"/>
    <mu2 value="100.0"/>
    <kp value="1000000.0"/>
    <kd value="1.0"/>
  </gazebo>
  <joint name="nav_kinect_joint" type="fixed">
    <origin rpy="0 0 0" xyz="0.031242 -0.0137160 0.022352"/>
    <parent link="nav_kinect_top_plate_link"/>
    <child link="nav_kinect_link"/>
  </joint>
  <link name="nav_kinect_link">
    <inertial>
      <mass value="0.1"/>
      <origin rpy="0 0 0" xyz="0 0 0"/>
      <inertia ixx="0.01" ixy="0.0" ixz="0.0" iyy="0.01" iyz="0.0" izz="0.01"/>
    </inertial>
    <visual>
      <origin rpy="0 0 0" xyz="0.0 0.012 0"/>
      <geometry>
        <mesh filename="package://pr2_description/meshes/sensors/kinect_v0/kinect.dae" scale="0.001 0.001 0.001"/>
      </geometry>
    </visual>
    <!-- <collision> -->
    <!--   <origin xyz="0.0 0.012 0" rpy="0 0 0"/> -->
    <!--   <geometry> -->
    <!--     <mesh filename="package://pr2_description/meshes/sensors/kinect_v0/kinect.dae" scale="0.001 0.001 0.001" /> -->
    <!--   </geometry> -->
    <!-- </collision> -->
  </link>
  <gazebo reference="nav_kinect_link">
    <sensor name="nav_kinect_link_sensor" type="depth">
      <always_on>true</always_on>
      <update_rate>20.0</update_rate>
      <camera>
        <horizontal_fov>0.994837673637</horizontal_fov>
        <image>
          <format>R8G8B8</format>
          <width>640</width>
          <height>480</height>
        </image>
        <clip>
          <near>0.01</near>
          <far>5</far>
        </clip>
      </camera>
      <plugin filename="libgazebo_ros_openni_kinect.so" name="nav_kinect_frame_controller">
        <alwaysOn>true</alwaysOn>
        <updateRate>20.0</updateRate>
        <cameraName>nav_kinect</cameraName>
        <imageTopicName>rgb/image_raw</imageTopicName>
        <cameraInfoTopicName>rgb/camera_info</cameraInfoTopicName>
        <depthImageTopicName>depth/image_raw</depthImageTopicName>
        <depthImageCameraInfoTopicName>depth/camera_info</depthImageCameraInfoTopicName>
        <pointCloudTopicName>depth/points</pointCloudTopicName>
        <frameName>nav_kinect_depth_optical_frame</frameName>
        <pointCloudCutoff>0.5</pointCloudCutoff>
        <distortionK1>0.00000001</distortionK1>
        <distortionK2>0.00000001</distortionK2>
        <distortionK3>0.00000001</distortionK3>
        <distortionT1>0.00000001</distortionT1>
        <distortionT2>0.00000001</distortionT2>
      </plugin>
    </sensor>
  </gazebo>
  <joint name="nav_kinect_link_joint1" type="fixed">
    <origin rpy="0 0 0" xyz="0 -0.02 0"/>
    <parent link="nav_kinect_link"/>
    <child link="nav_kinect_depth_frame"/>
  </joint>
  <link name="nav_kinect_depth_frame">
    <inertial>
      <mass value="0.001"/>
      <origin rpy="0 0 0" xyz="0 0 0"/>
      <inertia ixx="0.0001" ixy="0" ixz="0" iyy="0.000001" iyz="0" izz="0.0001"/>
    </inertial>
  </link>
  <joint name="nav_kinect_link_joint2" type="fixed">
    <origin rpy="0 0 0" xyz="0 -0.045 0"/>
    <parent link="nav_kinect_link"/>
    <child link="nav_kinect_rgb_frame"/>
  </joint>
  <link name="nav_kinect_rgb_frame">
    <inertial>
      <mass value="0.001"/>
      <origin rpy="0 0 0" xyz="0 0 0"/>
      <inertia ixx="0.0001" ixy="0" ixz="0" iyy="0.000001" iyz="0" izz="0.0001"/>
    </inertial>
  </link>
  <joint name="nav_kinect_link_joint3" type="fixed">
    <origin rpy="-1.5707963268 0 -1.5707963268" xyz="0 0 0"/>
    <parent link="nav_kinect_depth_frame"/>
    <child link="nav_kinect_depth_optical_frame"/>
  </joint>
  <link name="nav_kinect_depth_optical_frame">
    <inertial>
      <mass value="0.001"/>
      <origin rpy="0 0 0" xyz="0 0 0"/>
      <inertia ixx="0.0001" ixy="0" ixz="0" iyy="0.000001" iyz="0" izz="0.0001"/>
    </inertial>
  </link>
  <joint name="nav_kinect_link_joint4" type="fixed">
    <origin rpy="-1.5707963268 0 -1.5707963268" xyz="0 0 0"/>
    <parent link="nav_kinect_rgb_frame"/>
    <child link="nav_kinect_rgb_optical_frame"/>
  </joint>
  <link name="nav_kinect_rgb_optical_frame">
    <inertial>
      <mass value="0.001"/>
      <origin rpy="0 0 0" xyz="0 0 0"/>
      <inertia ixx="0.0001" ixy="0" ixz="0" iyy="0.000001" iyz="0" izz="0.0001"/>
    </inertial>
  </link>
  <!-- Add the shared beam between the hokuyo and the sensor plate -->
  <joint name="hokuyo_sonar_sensor_beam_joint" type="fixed">
    <origin rpy="1.5707963268 1.5707963268 0" xyz="0.0254 0.0127 0.1143"/>
    <parent link="front_left_vertical_beam_link"/>
    <child link="hokuyo_sonar_sensor_beam_link"/>
  </joint>
  <link name="hokuyo_sonar_sensor_beam_link">
    <inertial>
      <mass value="0.1"/>
      <inertia ixx="0.01" ixy="0.0" ixz="0.0" iyy="0.01" iyz="0.0" izz="0.01"/>
    </inertial>
    <visual>
      <origin rpy="0 0 0" xyz="0 0 0.1524"/>
      <geometry>
        <box size="0.0254 0.0254 0.3048"/>
      </geometry>
      <material name="light_grey"/>
    </visual>
  </link>
  <gazebo reference="hokuyo_sonar_sensor_beam_link">
    <material>Gazebo/Grey</material>
    <mu1 value="100.0"/>
    <mu2 value="100.0"/>
    <kp value="1000000.0"/>
    <kd value="1.0"/>
  </gazebo>
  <!-- Add the hokuyo mount without the beam -->
  <joint name="nav_hokuyo_plate_joint" type="fixed">
    <origin rpy="1.5707963268 0 1.5707963268" xyz="0.0127 0 0.1524"/>
    <parent link="hokuyo_sonar_sensor_beam_link"/>
    <child link="nav_hokuyo_plate_link"/>
  </joint>
  <link name="nav_hokuyo_plate_link">
    <inertial>
      <mass value="0.1"/>
      <origin rpy="0 0 0" xyz="0 0 0"/>
      <inertia ixx="0.01" ixy="0.0" ixz="0.0" iyy="0.01" iyz="0.0" izz="0.01"/>
    </inertial>
    <visual>
      <origin rpy="0 0 0" xyz="0 0 0.0015875"/>
      <geometry>
        <box size="0.06 0.12 0.003175"/>
      </geometry>
      <material name="dark_grey"/>
    </visual>
  </link>
  <gazebo reference="nav_hokuyo_plate_link">
    <material>Gazebo/Grey</material>
    <mu1 value="100.0"/>
    <mu2 value="100.0"/>
    <kp value="1000000.0"/>
    <kd value="1.0"/>
  </gazebo>
  <joint name="nav_hokuyo_joint" type="fixed">
    <axis xyz="0 1 0"/>
    <origin rpy="0 0 0" xyz="0 0 0.003175"/>
    <parent link="nav_hokuyo_plate_link"/>
    <child link="nav_hokuyo_link"/>
  </joint>
  <link name="nav_hokuyo_link">
    <inertial>
      <mass value="0.001"/>
      <origin rpy="0 0 0" xyz="0 0 0"/>
      <inertia ixx="0.0001" ixy="0" ixz="0" iyy="0.000001" iyz="0" izz="0.0001"/>
    </inertial>
    <visual>
      <origin rpy="0 0 0" xyz="0 0 0"/>
      <geometry>
        <mesh filename="package://segbot_description/meshes/hokuyo.dae" scale="0.0254 0.0254 0.0254"/>
      </geometry>
    </visual>
    <!-- ignore the collision element -->
  </link>
  <joint name="nav_hokuyo_laser_joint" type="fixed">
    <origin xyz="0 0 0.058"/>
    <parent link="nav_hokuyo_link"/>
    <child link="nav_hokuyo_laser_link"/>
  </joint>
  <link name="nav_hokuyo_laser_link" type="laser">
    <inertial>
      <mass value="0.001"/>
      <origin rpy="0 0 0" xyz="0 0 0"/>
      <inertia ixx="0.0001" ixy="0" ixz="0" iyy="0.000001" iyz="0" izz="0.0001"/>
    </inertial>
  </link>
  <gazebo reference="nav_hokuyo_laser_link">
    <sensor name="nav_hokuyo_laser" type="ray">
      <always_on>true</always_on>
      <update_rate>10</update_rate>
      <pose>0 0 0 0 0 0</pose>
      <visualize>false</visualize>
      <ray>
        <scan>
          <horizontal>
            <samples>640</samples>
            <resolution>1</resolution>
            <min_angle>-1.308996939</min_angle>
            <max_angle>1.308996939</max_angle>
          </horizontal>
        </scan>
        <range>
          <min>0.02</min>
          <max>20.0</max>
          <resolution>0.03</resolution>
        </range>
      </ray>
      <plugin filename="libgazebo_ros_laser.so" name="gazebo_ros_nav_hokuyo_laser_controller">
        <gaussianNoise>0.0</gaussianNoise>
        <alwaysOn>true</alwaysOn>
        <updateRate>10</updateRate>
        <topicName>scan</topicName>
        <frameName>nav_hokuyo_laser_link</frameName>
      </plugin>
    </sensor>
  </gazebo>
  <!-- Add the sensor plate mount -->
  <joint name="left_sensor_plate_standoff_joint" type="fixed">
    <origin rpy="-1.5707963268 0 1.5707963268" xyz="-0.0127 0 0.0889"/>
    <parent link="hokuyo_sonar_sensor_beam_link"/>
    <child link="left_sensor_plate_standoff_link"/>
  </joint>
  <link name="left_sensor_plate_standoff_link">
    <inertial>
      <mass value="0.1"/>
      <origin rpy="0 0 0" xyz="0 0 0"/>
      <inertia ixx="0.01" ixy="0.0" ixz="0.0" iyy="0.01" iyz="0.0" izz="0.01"/>
    </inertial>
    <visual>
      <origin rpy="0 0 0" xyz="0 0 0.00635"/>
      <geometry>
        <cylinder length="0.0127" radius="0.00635"/>
      </geometry>
      <material name="light_grey"/>
    </visual>
  </link>
  <gazebo reference="left_sensor_plate_standoff_link">
    <material>Gazebo/Grey</material>
    <mu1 value="100.0"/>
    <mu2 value="100.0"/>
    <kp value="1000000.0"/>
    <kd value="1.0"/>
  </gazebo>
  <joint name="right_sensor_plate_standoff_joint" type="fixed">
    <origin rpy="-1.5707963268 0 1.5707963268" xyz="-0.0127 0 0.2159"/>
    <parent link="hokuyo_sonar_sensor_beam_link"/>
    <child link="right_sensor_plate_standoff_link"/>
  </joint>
  <link name="right_sensor_plate_standoff_link">
    <inertial>
      <mass value="0.1"/>
      <origin rpy="0 0 0" xyz="0 0 0"/>
      <inertia ixx="0.01" ixy="0.0" ixz="0.0" iyy="0.01" iyz="0.0" izz="0.01"/>
    </inertial>
    <visual>
      <origin rpy="0 0 0" xyz="0 0 0.00635"/>
      <geometry>
        <cylinder length="0.0127" radius="0.00635"/>
      </geometry>
      <material name="light_grey"/>
    </visual>
  </link>
  <gazebo reference="right_sensor_plate_standoff_link">
    <material>Gazebo/Grey</material>
    <mu1 value="100.0"/>
    <mu2 value="100.0"/>
    <kp value="1000000.0"/>
    <kd value="1.0"/>
  </gazebo>
  <joint name="sensor_plate_joint" type="fixed">
    <origin rpy="0 0 0" xyz="-0.00635 -0.0635 0.0127"/>
    <parent link="left_sensor_plate_standoff_link"/>
    <child link="sensor_plate_link"/>
  </joint>
  <link name="sensor_plate_link">
    <inertial>
      <mass value="0.1"/>
      <origin rpy="0 0 0" xyz="0 0 0"/>
      <inertia ixx="0.01" ixy="0.0" ixz="0.0" iyy="0.01" iyz="0.0" izz="0.01"/>
    </inertial>
    <visual>
      <origin rpy="0 0 0" xyz="0 0 0.0015"/>
      <geometry>
        <box size="0.1143 0.2286 0.003"/>
      </geometry>
      <material name="dark_grey"/>
    </visual>
  </link>
  <gazebo reference="sensor_plate_link">
    <material>Gazebo/Grey</material>
    <mu1 value="100.0"/>
    <mu2 value="100.0"/>
    <kp value="1000000.0"/>
    <kd value="1.0"/>
  </gazebo>
  <joint name="sonar_center_joint" type="fixed">
    <origin xyz="-0.217932 0 0.015"/>
    <parent link="sensor_plate_link"/>
    <child link="sonar_center_link"/>
  </joint>
  <link name="sonar_center_link">
    <inertial>
      <mass value="0.1"/>
      <origin rpy="0 0 0" xyz="0 0 0"/>
      <inertia ixx="0.01" ixy="0.0" ixz="0.0" iyy="0.01" iyz="0.0" izz="0.01"/>
    </inertial>
    <visual>
      <origin rpy="0 0 0" xyz="0 0 0"/>
      <geometry>
        <box size="0.001 0.001 0.001"/>
      </geometry>
    </visual>
  </link>
  <joint name="sonar0_rotated_center_joint" type="fixed">
    <origin rpy="0 0 -0.349065850399" xyz="0 0 0"/>
    <parent link="sonar_center_link"/>
    <child link="sonar0_rotated_center_link"/>
  </joint>
  <link name="sonar0_rotated_center_link">
    <inertial>
      <mass value="0.1"/>
      <origin rpy="0 0 0" xyz="0 0 0"/>
      <inertia ixx="0.01" ixy="0.0" ixz="0.0" iyy="0.01" iyz="0.0" izz="0.01"/>
    </inertial>
    <visual>
      <origin rpy="0 0 0" xyz="0 0 0"/>
      <geometry>
        <box size="0.001 0.001 0.001"/>
      </geometry>
    </visual>
  </link>
  <joint name="sonar0_joint" type="fixed">
    <origin xyz="0.262382 0 0"/>
    <parent link="sonar0_rotated_center_link"/>
    <child link="sonar0_link"/>
  </joint>
  <link name="sonar0_link">
    <inertial>
      <mass value="0.1"/>
      <origin rpy="0 0 0" xyz="0 0 0"/>
      <inertia ixx="0.01" ixy="0.0" ixz="0.0" iyy="0.01" iyz="0.0" izz="0.01"/>
    </inertial>
    <visual>
      <origin rpy="0 0 0" xyz="0 0 0"/>
      <geometry>
        <box size="0.012 0.044 0.023"/>
      </geometry>
    </visual>
  </link>
  <joint name="sonar1_joint" type="fixed">
    <origin xyz="0.262382 0 0"/>
    <parent link="sonar_center_link"/>
    <child link="sonar1_link"/>
  </joint>
  <link name="sonar1_link">
    <inertial>
      <mass value="0.1"/>
      <origin rpy="0 0 0" xyz="0 0 0"/>
      <inertia ixx="0.01" ixy="0.0" ixz="0.0" iyy="0.01" iyz="0.0" izz="0.01"/>
    </inertial>
    <visual>
      <origin rpy="0 0 0" xyz="0 0 0"/>
      <geometry>
        <box size="0.012 0.044 0.023"/>
      </geometry>
    </visual>
  </link>
  <joint name="sonar2_rotated_center_joint" type="fixed">
    <origin rpy="0 0 0.349065850399" xyz="0 0 0"/>
    <parent link="sonar_center_link"/>
    <child link="sonar2_rotated_center_link"/>
  </joint>
  <link name="sonar2_rotated_center_link">
    <inertial>
      <mass value="0.1"/>
      <origin rpy="0 0 0" xyz="0 0 0"/>
      <inertia ixx="0.01" ixy="0.0" ixz="0.0" iyy="0.01" iyz="0.0" izz="0.01"/>
    </inertial>
    <visual>
      <origin rpy="0 0 0" xyz="0 0 0"/>
      <geometry>
        <box size="0.001 0.001 0.001"/>
      </geometry>
    </visual>
  </link>
  <joint name="sonar2_joint" type="fixed">
    <origin xyz="0.262382 0 0"/>
    <parent link="sonar2_rotated_center_link"/>
    <child link="sonar2_link"/>
  </joint>
  <link name="sonar2_link">
    <inertial>
      <mass value="0.1"/>
      <origin rpy="0 0 0" xyz="0 0 0"/>
      <inertia ixx="0.01" ixy="0.0" ixz="0.0" iyy="0.01" iyz="0.0" izz="0.01"/>
    </inertial>
    <visual>
      <origin rpy="0 0 0" xyz="0 0 0"/>
      <geometry>
        <box size="0.012 0.044 0.023"/>
      </geometry>
    </visual>
  </link>
  <!-- Add the left sensor beam -->
  <joint name="left_sensor_beam_joint" type="fixed">
    <origin rpy="0 0 0" xyz="-0.1143 0.2159 0.003175"/>
    <parent link="laptop_base_plate_link"/>
    <child link="left_sensor_beam_link"/>
  </joint>
  <link name="left_sensor_beam_link">
    <inertial>
      <mass value="0.1"/>
      <inertia ixx="0.01" ixy="0.0" ixz="0.0" iyy="0.01" iyz="0.0" izz="0.01"/>
    </inertial>
    <visual>
      <origin rpy="0 0 0" xyz="0 0 0.381"/>
      <geometry>
        <box size="0.0254 0.0254 0.762"/>
      </geometry>
      <material name="light_grey"/>
    </visual>
  </link>
  <gazebo reference="left_sensor_beam_link">
    <material>Gazebo/Grey</material>
    <mu1 value="100.0"/>
    <mu2 value="100.0"/>
    <kp value="1000000.0"/>
    <kd value="1.0"/>
  </gazebo>
  <!-- Add the right sensor beam -->
  <joint name="right_sensor_beam_joint" type="fixed">
    <origin rpy="0 0 0" xyz="-0.1143 -0.2159 0.003175"/>
    <parent link="laptop_base_plate_link"/>
    <child link="right_sensor_beam_link"/>
  </joint>
  <link name="right_sensor_beam_link">
    <inertial>
      <mass value="0.1"/>
      <inertia ixx="0.01" ixy="0.0" ixz="0.0" iyy="0.01" iyz="0.0" izz="0.01"/>
    </inertial>
    <visual>
      <origin rpy="0 0 0" xyz="0 0 0.381"/>
      <geometry>
        <box size="0.0254 0.0254 0.762"/>
      </geometry>
      <material name="light_grey"/>
    </visual>
  </link>
  <gazebo reference="right_sensor_beam_link">
    <material>Gazebo/Grey</material>
    <mu1 value="100.0"/>
    <mu2 value="100.0"/>
    <kp value="1000000.0"/>
    <kd value="1.0"/>
  </gazebo>
  <!-- Add the top sensor beam -->
  <joint name="top_sensor_beam_joint" type="fixed">
    <origin rpy="-1.5707963268 0 0" xyz="0 -0.0127 0.7747"/>
    <parent link="right_sensor_beam_link"/>
    <child link="top_sensor_beam_link"/>
  </joint>
  <link name="top_sensor_beam_link">
    <inertial>
      <mass value="0.1"/>
      <inertia ixx="0.01" ixy="0.0" ixz="0.0" iyy="0.01" iyz="0.0" izz="0.01"/>
    </inertial>
    <visual>
      <origin rpy="0 0 0" xyz="0 0 0.2286"/>
      <geometry>
        <box size="0.0254 0.0254 0.4572"/>
      </geometry>
      <material name="light_grey"/>
    </visual>
  </link>
  <gazebo reference="top_sensor_beam_link">
    <material>Gazebo/Grey</material>
    <mu1 value="100.0"/>
    <mu2 value="100.0"/>
    <kp value="1000000.0"/>
    <kd value="1.0"/>
  </gazebo>
  <!-- add the arm -->
  <!--this is needed as the mico_arm xacro file doesn't accept origin as argument -->
  <joint name="arm_fixed_joint" type="fixed">
    <origin rpy="0 0 0.0" xyz="0.1524 0 0.0381"/>
    <parent link="laptop_base_plate_link"/>
    <child link="arm_link"/>
  </joint>
  <link name="arm_link">
    <visual>
      <origin rpy="0 0 0" xyz="0 0 0"/>
      <geometry>
        <box size="0 0 0"/>
        <!--making it slightly bigger in x and z direction-->
      </geometry>
      <!--<material name="Black" /> -->
    </visual>
    <collision>
      <origin rpy="0 0 0" xyz="0 0 0"/>
      <geometry>
        <box size="0 0 0"/>
        <!--making it slightly bigger in x and z direction-->
      </geometry>
    </collision>
  </link>
  <link name="mico_link_base">
    <visual>
      <geometry>
        <mesh filename="package://jaco_model/meshes/mico_link_base.dae"/>
      </geometry>
      <material name="carbon_fiber">
        <color rgba="0.792156862745098 0.819607843137255 0.933333333333333 1"/>
      </material>
    </visual>
    <collision>
      <geometry>
        <mesh filename="package://jaco_model/meshes/mico_link_base.dae"/>
      </geometry>
    </collision>
  </link>
  <joint name="mico_joint_base" type="fixed">
    <parent link="arm_link"/>
    <child link="mico_link_base"/>
    <axis xyz="0 0 0"/>
    <limit effort="30" lower="0" upper="0" velocity="0.35"/>
    <origin rpy="0 0 0" xyz="0 0 0"/>
  </joint>
  <link name="mico_link_1">
    <visual>
      <geometry>
        <mesh filename="package://jaco_model/meshes/mico_link_1.dae"/>
      </geometry>
      <material name="carbon_fiber">
        <color rgba="0.792156862745098 0.819607843137255 0.933333333333333 1"/>
      </material>
    </visual>
    <collision>
      <geometry>
        <mesh filename="package://jaco_model/meshes/mico_link_1.dae"/>
      </geometry>
    </collision>
  </link>
  <joint name="mico_joint_1" type="continuous">
    <parent link="mico_link_base"/>
    <child link="mico_link_1"/>
    <axis xyz="0 0 -1"/>
    <limit effort="30" lower="-6.28318530718" upper="6.28318530718" velocity="0.35"/>
    <origin rpy="3.14159265359 0 3.14159265359" xyz="0 0 0.1535"/>
  </joint>
  <link name="mico_link_2">
    <visual>
      <geometry>
        <mesh filename="package://jaco_model/meshes/mico_link_2.dae"/>
      </geometry>
      <material name="carbon_fiber">
        <color rgba="0.792156862745098 0.819607843137255 0.933333333333333 1"/>
      </material>
    </visual>
    <collision>
      <geometry>
        <mesh filename="package://jaco_model/meshes/mico_link_2.dae"/>
      </geometry>
    </collision>
  </link>
  <joint name="mico_joint_2" type="revolute">
    <parent link="mico_link_1"/>
    <child link="mico_link_2"/>
    <axis xyz="0 0 1"/>
    <limit effort="30" lower="-3.59159265359" upper="0.45" velocity="0.35"/>
    <origin rpy="-1.57079632679 3.14159265359 0" xyz="0 0 -0.1185"/>
  </joint>
  <link name="mico_link_3">
    <visual>
      <geometry>
        <mesh filename="package://jaco_model/meshes/mico_link_3.dae"/>
      </geometry>
      <material name="carbon_fiber">
        <color rgba="0.792156862745098 0.819607843137255 0.933333333333333 1"/>
      </material>
    </visual>
    <collision>
      <geometry>
        <mesh filename="package://jaco_model/meshes/mico_link_3.dae"/>
      </geometry>
    </collision>
  </link>
  <joint name="mico_joint_3" type="revolute">
    <parent link="mico_link_2"/>
    <child link="mico_link_3"/>
    <axis xyz="0 0 -1"/>
    <limit effort="30" lower="-3.92699081699" upper="0.785398163397" velocity="0.35"/>
    <origin rpy="3.14159265359 0 1.57079632679" xyz="0.29 0 0"/>
  </joint>
  <link name="mico_link_4">
    <visual>
      <geometry>
        <mesh filename="package://jaco_model/meshes/mico_link_4.dae"/>
      </geometry>
      <material name="carbon_fiber">
        <color rgba="0.792156862745098 0.819607843137255 0.933333333333333 1"/>
      </material>
    </visual>
    <collision>
      <geometry>
        <mesh filename="package://jaco_model/meshes/mico_link_4.dae"/>
      </geometry>
    </collision>
  </link>
  <joint name="mico_joint_4" type="continuous">
    <parent link="mico_link_3"/>
    <child link="mico_link_4"/>
    <axis xyz="0 0 -1"/>
    <limit effort="30" lower="-6.28318530718" upper="6.28318530718" velocity="0.35"/>
    <origin rpy="3.14159265359 1.57079632679 0" xyz="0.123 0 -0.00845"/>
  </joint>
  <link name="mico_link_5">
    <visual>
      <geometry>
        <mesh filename="package://jaco_model/meshes/mico_link_5.dae"/>
      </geometry>
      <material name="carbon_fiber">
        <color rgba="0.792156862745098 0.819607843137255 0.933333333333333 1"/>
      </material>
    </visual>
    <collision>
      <geometry>
        <mesh filename="package://jaco_model/meshes/mico_link_5.dae"/>
      </geometry>
    </collision>
  </link>
  <joint name="mico_joint_5" type="continuous">
    <parent link="mico_link_4"/>
    <child link="mico_link_5"/>
    <axis xyz="0 0 -1"/>
    <limit effort="30" lower="-6.28318530718" upper="6.28318530718" velocity="0.35"/>
    <origin rpy="0 -1.0471975512 0" xyz="0.03700 0 -0.06408"/>
  </joint>
  <link name="mico_link_hand">
    <visual>
      <geometry>
        <mesh filename="package://jaco_model/meshes/mico_link_hand.dae"/>
      </geometry>
      <material name="carbon_fiber">
        <color rgba="0.792156862745098 0.819607843137255 0.933333333333333 1"/>
      </material>
    </visual>
    <collision>
      <geometry>
        <mesh filename="package://jaco_model/meshes/mico_link_hand.dae"/>
      </geometry>
    </collision>
  </link>
  <joint name="mico_joint_6" type="continuous">
    <parent link="mico_link_5"/>
    <child link="mico_link_hand"/>
    <axis xyz="0 0 -1"/>
    <limit effort="30" lower="-6.28318530718" upper="6.28318530718" velocity="0.35"/>
    <origin rpy="-1.0471975512 0 1.57079632679" xyz="0.03700 0 -0.06408"/>
  </joint>
  <joint name="mico_link_base_to_api_origin" type="fixed">
    <parent link="mico_link_base"/>
    <child link="mico_api_origin"/>
    <origin rpy="0 0 0" xyz="0 0 0.028"/>
  </joint>
  <link name="mico_api_origin">
    <!--
         <visual>
           <geometry>
             <box xyz="0 0 0" size="0.1 0.1 0.1"/>
           </geometry>
         </visual>
         <collision>
           <geometry>
             <box xyz="0 0 0" size="0.1 0.1 0.1"/>
           </geometry>
         </collision>
         -->
  </link>
  <joint name="mico_link_hand_to_end_effector" type="fixed">
    <parent link="mico_link_hand"/>
    <child link="mico_end_effector"/>
    <origin rpy="0 3.14159265359 0" xyz="0 0 -0.16"/>
  </joint>
  <link name="mico_end_effector"/>
  <link name="mico_link_finger_1">
    <visual>
      <geometry>
        <mesh filename="package://jaco_model/meshes/mico_link_finger_1.dae"/>
      </geometry>
      <material name="carbon_fiber">
        <color rgba="0.792156862745098 0.819607843137255 0.933333333333333 1"/>
      </material>
    </visual>
    <collision>
      <geometry>
        <mesh filename="package://jaco_model/meshes/mico_link_finger_1.dae"/>
      </geometry>
    </collision>
  </link>
  <joint name="mico_joint_finger_1" type="revolute">
    <parent link="mico_link_hand"/>
    <child link="mico_link_finger_1"/>
    <axis xyz="0 0 1"/>
    <origin rpy="-1.57079632679 1.117 3.14159265359" xyz="-0.03978 0 -0.10071"/>
    <limit effort="30" lower="0" upper="0.698131700798" velocity="5"/>
  </joint>
  <link name="mico_link_finger_2">
    <visual>
      <geometry>
        <mesh filename="package://jaco_model/meshes/mico_link_finger_2.dae"/>
      </geometry>
      <material name="carbon_fiber">
        <color rgba="0.792156862745098 0.819607843137255 0.933333333333333 1"/>
      </material>
    </visual>
    <collision>
      <geometry>
        <mesh filename="package://jaco_model/meshes/mico_link_finger_2.dae"/>
      </geometry>
    </collision>
  </link>
  <joint name="mico_joint_finger_2" type="revolute">
    <parent link="mico_link_hand"/>
    <child link="mico_link_finger_2"/>
    <axis xyz="0 0 1"/>
    <origin rpy="1.57079632679 2.02459265359 3.14159265359" xyz="0.03569 0 -0.10071"/>
    <limit effort="30" lower="0" upper="0.698131700798" velocity="5"/>
  </joint>
  <!-- add the xtion -->
  <joint name="xtion_camera_joint" type="fixed">
    <origin rpy="0 0.74 0" xyz="-0.245 +0.05 0.75"/>
    <parent link="arm_link"/>
    <child link="xtion_camera_link"/>
  </joint>
  <link name="xtion_camera_link">
    <inertial>
      <mass value="0.1"/>
      <origin rpy="0 0 0" xyz="0 0 0"/>
      <inertia ixx="0.01" ixy="0.0" ixz="0.0" iyy="0.01" iyz="0.0" izz="0.01"/>
    </inertial>
    <visual>
      <origin rpy="0 0 0" xyz="0.0 0.012 0"/>
      <geometry>
        <mesh filename="package://pr2_description/meshes/sensors/kinect_v0/kinect.dae" scale="0.001 0.001 0.001"/>
      </geometry>
    </visual>
    <!-- <collision> -->
    <!--   <origin xyz="0.0 0.012 0" rpy="0 0 0"/> -->
    <!--   <geometry> -->
    <!--     <mesh filename="package://pr2_description/meshes/sensors/kinect_v0/kinect.dae" scale="0.001 0.001 0.001" /> -->
    <!--   </geometry> -->
    <!-- </collision> -->
  </link>
  <gazebo reference="xtion_camera_link">
    <sensor name="xtion_camera_link_sensor" type="depth">
      <always_on>true</always_on>
      <update_rate>20.0</update_rate>
      <camera>
        <horizontal_fov>0.994837673637</horizontal_fov>
        <image>
          <format>R8G8B8</format>
          <width>640</width>
          <height>480</height>
        </image>
        <clip>
          <near>0.01</near>
          <far>5</far>
        </clip>
      </camera>
      <plugin filename="libgazebo_ros_openni_kinect.so" name="xtion_camera_frame_controller">
        <alwaysOn>true</alwaysOn>
        <updateRate>20.0</updateRate>
        <cameraName>xtion_camera</cameraName>
        <imageTopicName>rgb/image_raw</imageTopicName>
        <cameraInfoTopicName>rgb/camera_info</cameraInfoTopicName>
        <depthImageTopicName>depth/image_raw</depthImageTopicName>
        <depthImageCameraInfoTopicName>depth/camera_info</depthImageCameraInfoTopicName>
        <pointCloudTopicName>depth/points</pointCloudTopicName>
        <frameName>xtion_camera_depth_optical_frame</frameName>
        <pointCloudCutoff>0.5</pointCloudCutoff>
        <distortionK1>0.00000001</distortionK1>
        <distortionK2>0.00000001</distortionK2>
        <distortionK3>0.00000001</distortionK3>
        <distortionT1>0.00000001</distortionT1>
        <distortionT2>0.00000001</distortionT2>
      </plugin>
    </sensor>
  </gazebo>
  <joint name="xtion_camera_link_joint1" type="fixed">
    <origin rpy="0 0 0" xyz="0 -0.02 0"/>
    <parent link="xtion_camera_link"/>
    <child link="xtion_camera_depth_frame"/>
  </joint>
  <link name="xtion_camera_depth_frame">
    <inertial>
      <mass value="0.001"/>
      <origin rpy="0 0 0" xyz="0 0 0"/>
      <inertia ixx="0.0001" ixy="0" ixz="0" iyy="0.000001" iyz="0" izz="0.0001"/>
    </inertial>
  </link>
  <joint name="xtion_camera_link_joint2" type="fixed">
    <origin rpy="0 0 0" xyz="0 -0.045 0"/>
    <parent link="xtion_camera_link"/>
    <child link="xtion_camera_rgb_frame"/>
  </joint>
  <link name="xtion_camera_rgb_frame">
    <inertial>
      <mass value="0.001"/>
      <origin rpy="0 0 0" xyz="0 0 0"/>
      <inertia ixx="0.0001" ixy="0" ixz="0" iyy="0.000001" iyz="0" izz="0.0001"/>
    </inertial>
  </link>
  <joint name="xtion_camera_link_joint3" type="fixed">
    <origin rpy="-1.5707963268 0 -1.5707963268" xyz="0 0 0"/>
    <parent link="xtion_camera_depth_frame"/>
    <child link="xtion_camera_depth_optical_frame"/>
  </joint>
  <link name="xtion_camera_depth_optical_frame">
    <inertial>
      <mass value="0.001"/>
      <origin rpy="0 0 0" xyz="0 0 0"/>
      <inertia ixx="0.0001" ixy="0" ixz="0" iyy="0.000001" iyz="0" izz="0.0001"/>
    </inertial>
  </link>
  <joint name="xtion_camera_link_joint4" type="fixed">
    <origin rpy="-1.5707963268 0 -1.5707963268" xyz="0 0 0"/>
    <parent link="xtion_camera_rgb_frame"/>
    <child link="xtion_camera_rgb_optical_frame"/>
  </joint>
  <link name="xtion_camera_rgb_optical_frame">
    <inertial>
      <mass value="0.001"/>
      <origin rpy="0 0 0" xyz="0 0 0"/>
      <inertia ixx="0.0001" ixy="0" ixz="0" iyy="0.000001" iyz="0" izz="0.0001"/>
    </inertial>
  </link>
  <gazebo>
    <plugin filename="libgazebo_ros_planar_move.so" name="object_controller">
      <commandTopic>cmd_vel</commandTopic>
      <odometryTopic>odom</odometryTopic>
      <odometryFrame>odom</odometryFrame>
      <robotBaseFrame>base_footprint</robotBaseFrame>
      <odometryRate>100</odometryRate>
    </plugin>
  </gazebo>
</robot>

